Workbook

Sheet Runway assumptions
A1: Runway assumptions
A2: Cash runway · Main Scenario
A4: Variable / dimension | B4: Value
A5: Avg bisects per customer | B5: =50 -> 50
A6: New customer growth | B6: =0.1 -> 0.1
A7: Monthly churn | B7: =0.03 -> 0.03

Sheet Plan mix
A1: Plan mix
A2: Cash runway · Main Scenario
A4: Variable / dimension | B4: Plan mix | C4: Revenue per customer at avg volume | D4: Gross profit per customer at avg volume | E4: Weighted revenue per customer | F4: Weighted gross profit per customer
A5: A · Flat $199/repo | B5: =0 -> 0 | C5: ='Model inputs'!B31*'Model inputs'!B27+'Model inputs'!B22*'Runway assumptions'!B5 -> 199 | D5: ='Plan mix'!C5-(1-'Model inputs'!B10)*'Runway assumptions'!B5*SUM('Model inputs'!B15,'Model inputs'!B16,'Model inputs'!B17)-IF(IF(IF(IF(ISERROR('Plan mix'!C5>0),'Plan mix'!C5>0,IF('Plan mix'!C5="","",'Plan mix'!C5>0))="",FALSE,IF(ISERROR('Plan mix'!C5>0),'Plan mix'!C5>0,IF('Plan mix'!C5="","",'Plan mix'!C5>0))),'Plan mix'!C5*'Model inputs'!B8+'Model inputs'!B7,0)="",0,IF(IF(IF(ISERROR('Plan mix'!C5>0),'Plan mix'!C5>0,IF('Plan mix'!C5="","",'Plan mix'!C5>0))="",FALSE,IF(ISERROR('Plan mix'!C5>0),'Plan mix'!C5>0,IF('Plan mix'!C5="","",'Plan mix'!C5>0))),'Plan mix'!C5*'Model inputs'!B8+'Model inputs'!B7,0)) -> 180.329 | E5: ='Plan mix'!B5*'Plan mix'!C5 -> 0 | F5: ='Plan mix'!B5*'Plan mix'!D5 -> 0
A6: A · Flat $49/repo | B6: =0 -> 0 | C6: ='Model inputs'!B31*'Model inputs'!B28+'Model inputs'!B23*'Runway assumptions'!B5 -> 49 | D6: ='Plan mix'!C6-(1-'Model inputs'!B11)*'Runway assumptions'!B5*SUM('Model inputs'!B15,'Model inputs'!B16,'Model inputs'!B17)-IF(IF(IF(IF(ISERROR('Plan mix'!C6>0),'Plan mix'!C6>0,IF('Plan mix'!C6="","",'Plan mix'!C6>0))="",FALSE,IF(ISERROR('Plan mix'!C6>0),'Plan mix'!C6>0,IF('Plan mix'!C6="","",'Plan mix'!C6>0))),'Plan mix'!C6*'Model inputs'!B8+'Model inputs'!B7,0)="",0,IF(IF(IF(ISERROR('Plan mix'!C6>0),'Plan mix'!C6>0,IF('Plan mix'!C6="","",'Plan mix'!C6>0))="",FALSE,IF(ISERROR('Plan mix'!C6>0),'Plan mix'!C6>0,IF('Plan mix'!C6="","",'Plan mix'!C6>0))),'Plan mix'!C6*'Model inputs'!B8+'Model inputs'!B7,0)) -> 34.679 | E6: ='Plan mix'!B6*'Plan mix'!C6 -> 0 | F6: ='Plan mix'!B6*'Plan mix'!D6 -> 0
A7: B · BYOK + $99/repo | B7: =1 -> 1 | C7: ='Model inputs'!B31*'Model inputs'!B29+'Model inputs'!B24*'Runway assumptions'!B5 -> 99 | D7: ='Plan mix'!C7-(1-'Model inputs'!B12)*'Runway assumptions'!B5*SUM('Model inputs'!B15,'Model inputs'!B16,'Model inputs'!B17)-IF(IF(IF(IF(ISERROR('Plan mix'!C7>0),'Plan mix'!C7>0,IF('Plan mix'!C7="","",'Plan mix'!C7>0))="",FALSE,IF(ISERROR('Plan mix'!C7>0),'Plan mix'!C7>0,IF('Plan mix'!C7="","",'Plan mix'!C7>0))),'Plan mix'!C7*'Model inputs'!B8+'Model inputs'!B7,0)="",0,IF(IF(IF(ISERROR('Plan mix'!C7>0),'Plan mix'!C7>0,IF('Plan mix'!C7="","",'Plan mix'!C7>0))="",FALSE,IF(ISERROR('Plan mix'!C7>0),'Plan mix'!C7>0,IF('Plan mix'!C7="","",'Plan mix'!C7>0))),'Plan mix'!C7*'Model inputs'!B8+'Model inputs'!B7,0)) -> 95.829 | E7: ='Plan mix'!B7*'Plan mix'!C7 -> 99 | F7: ='Plan mix'!B7*'Plan mix'!D7 -> 95.829
A8: C · $5 per bisect | B8: =0 -> 0 | C8: ='Model inputs'!B31*'Model inputs'!B30+'Model inputs'!B25*'Runway assumptions'!B5 -> 250 | D8: ='Plan mix'!C8-(1-'Model inputs'!B13)*'Runway assumptions'!B5*SUM('Model inputs'!B15,'Model inputs'!B16,'Model inputs'!B17)-IF(IF(IF(IF(ISERROR('Plan mix'!C8>0),'Plan mix'!C8>0,IF('Plan mix'!C8="","",'Plan mix'!C8>0))="",FALSE,IF(ISERROR('Plan mix'!C8>0),'Plan mix'!C8>0,IF('Plan mix'!C8="","",'Plan mix'!C8>0))),'Plan mix'!C8*'Model inputs'!B8+'Model inputs'!B7,0)="",0,IF(IF(IF(ISERROR('Plan mix'!C8>0),'Plan mix'!C8>0,IF('Plan mix'!C8="","",'Plan mix'!C8>0))="",FALSE,IF(ISERROR('Plan mix'!C8>0),'Plan mix'!C8>0,IF('Plan mix'!C8="","",'Plan mix'!C8>0))),'Plan mix'!C8*'Model inputs'!B8+'Model inputs'!B7,0)) -> 229.85 | E8: ='Plan mix'!B8*'Plan mix'!C8 -> 0 | F8: ='Plan mix'!B8*'Plan mix'!D8 -> 0

Sheet Monthly cash runway
A1: Monthly cash runway
A2: Cash runway · Main Scenario
A4: Variable / dimension | B4: 2026-09 | C4: 2026-10 | D4: 2026-11 | E4: 2026-12 | F4: 2027-01 | G4: 2027-02 | H4: 2027-03 | I4: 2027-04 | J4: 2027-05 | K4: 2027-06 | L4: 2027-07 | M4: 2027-08 | N4: 2027-09 | O4: 2027-10 | P4: 2027-11 | Q4: 2027-12 | R4: 2028-01 | S4: 2028-02 | T4: 2028-03 | U4: 2028-04 | V4: 2028-05 | W4: 2028-06 | X4: 2028-07 | Y4: 2028-08 | Z4: 2028-09
A5: New customers | B5: =5 -> 5 | C5: ='Monthly cash runway'!B5*(1+'Runway assumptions'!B6) -> 5.5 | D5: ='Monthly cash runway'!C5*(1+'Runway assumptions'!B6) -> 6.05 | E5: ='Monthly cash runway'!D5*(1+'Runway assumptions'!B6) -> 6.655 | F5: ='Monthly cash runway'!E5*(1+'Runway assumptions'!B6) -> 7.3205 | G5: ='Monthly cash runway'!F5*(1+'Runway assumptions'!B6) -> 8.05255 | H5: ='Monthly cash runway'!G5*(1+'Runway assumptions'!B6) -> 8.857805 | I5: ='Monthly cash runway'!H5*(1+'Runway assumptions'!B6) -> 9.7435855 | J5: ='Monthly cash runway'!I5*(1+'Runway assumptions'!B6) -> 10.717944 | K5: ='Monthly cash runway'!J5*(1+'Runway assumptions'!B6) -> 11.789738 | L5: ='Monthly cash runway'!K5*(1+'Runway assumptions'!B6) -> 12.968712 | M5: ='Monthly cash runway'!L5*(1+'Runway assumptions'!B6) -> 14.265584 | N5: ='Monthly cash runway'!M5*(1+'Runway assumptions'!B6) -> 15.692142 | O5: ='Monthly cash runway'!N5*(1+'Runway assumptions'!B6) -> 17.261356 | P5: ='Monthly cash runway'!O5*(1+'Runway assumptions'!B6) -> 18.987492 | Q5: ='Monthly cash runway'!P5*(1+'Runway assumptions'!B6) -> 20.886241 | R5: ='Monthly cash runway'!Q5*(1+'Runway assumptions'!B6) -> 22.974865 | S5: ='Monthly cash runway'!R5*(1+'Runway assumptions'!B6) -> 25.272351 | T5: ='Monthly cash runway'!S5*(1+'Runway assumptions'!B6) -> 27.799587 | U5: ='Monthly cash runway'!T5*(1+'Runway assumptions'!B6) -> 30.579545 | V5: ='Monthly cash runway'!U5*(1+'Runway assumptions'!B6) -> 33.6375 | W5: ='Monthly cash runway'!V5*(1+'Runway assumptions'!B6) -> 37.00125 | X5: ='Monthly cash runway'!W5*(1+'Runway assumptions'!B6) -> 40.701375 | Y5: ='Monthly cash runway'!X5*(1+'Runway assumptions'!B6) -> 44.771512 | Z5: ='Monthly cash runway'!Y5*(1+'Runway assumptions'!B6) -> 49.248663
A6: Churned customers | B6: 0 | C6: ='Monthly cash runway'!B7*'Runway assumptions'!B7 -> 0.15 | D6: ='Monthly cash runway'!C7*'Runway assumptions'!B7 -> 0.3105 | E6: ='Monthly cash runway'!D7*'Runway assumptions'!B7 -> 0.482685 | F6: ='Monthly cash runway'!E7*'Runway assumptions'!B7 -> 0.66785445 | G6: ='Monthly cash runway'!F7*'Runway assumptions'!B7 -> 0.86743382 | H6: ='Monthly cash runway'!G7*'Runway assumptions'!B7 -> 1.0829873 | I6: ='Monthly cash runway'!H7*'Runway assumptions'!B7 -> 1.3162318 | J6: ='Monthly cash runway'!I7*'Runway assumptions'!B7 -> 1.5690524 | K6: ='Monthly cash runway'!J7*'Runway assumptions'!B7 -> 1.8435192 | L6: ='Monthly cash runway'!K7*'Runway assumptions'!B7 -> 2.1419058 | M6: ='Monthly cash runway'!L7*'Runway assumptions'!B7 -> 2.46671 | N6: ='Monthly cash runway'!M7*'Runway assumptions'!B7 -> 2.8206762 | O6: ='Monthly cash runway'!N7*'Runway assumptions'!B7 -> 3.2068201 | P6: ='Monthly cash runway'!O7*'Runway assumptions'!B7 -> 3.6284562 | Q6: ='Monthly cash runway'!P7*'Runway assumptions'!B7 -> 4.0892273 | R6: ='Monthly cash runway'!Q7*'Runway assumptions'!B7 -> 4.5931377 | S6: ='Monthly cash runway'!R7*'Runway assumptions'!B7 -> 5.1445895 | T6: ='Monthly cash runway'!S7*'Runway assumptions'!B7 -> 5.7484224 | U6: ='Monthly cash runway'!T7*'Runway assumptions'!B7 -> 6.4099573 | V6: ='Monthly cash runway'!U7*'Runway assumptions'!B7 -> 7.1350449 | W6: ='Monthly cash runway'!V7*'Runway assumptions'!B7 -> 7.9301186 | X6: ='Monthly cash runway'!W7*'Runway assumptions'!B7 -> 8.8022525 | Y6: ='Monthly cash runway'!X7*'Runway assumptions'!B7 -> 9.7592262 | Z6: ='Monthly cash runway'!Y7*'Runway assumptions'!B7 -> 10.809595
A7: Paying customers | B7: =5 -> 5 | C7: ='Monthly cash runway'!B7+'Monthly cash runway'!C5-'Monthly cash runway'!C6 -> 10.35 | D7: ='Monthly cash runway'!C7+'Monthly cash runway'!D5-'Monthly cash runway'!D6 -> 16.0895 | E7: ='Monthly cash runway'!D7+'Monthly cash runway'!E5-'Monthly cash runway'!E6 -> 22.261815 | F7: ='Monthly cash runway'!E7+'Monthly cash runway'!F5-'Monthly cash runway'!F6 -> 28.914461 | G7: ='Monthly cash runway'!F7+'Monthly cash runway'!G5-'Monthly cash runway'!G6 -> 36.099577 | H7: ='Monthly cash runway'!G7+'Monthly cash runway'!H5-'Monthly cash runway'!H6 -> 43.874394 | I7: ='Monthly cash runway'!H7+'Monthly cash runway'!I5-'Monthly cash runway'!I6 -> 52.301748 | J7: ='Monthly cash runway'!I7+'Monthly cash runway'!J5-'Monthly cash runway'!J6 -> 61.45064 | ... Z7: ='Monthly cash runway'!Y7+'Monthly cash runway'!Z5-'Monthly cash runway'!Z6 -> 398.75889
A8: Monthly revenue | B8: 0 | C8: ='Monthly cash runway'!C7*SUM('Plan mix'!E5,'Plan mix'!E6,'Plan mix'!E7,'Plan mix'!E8) -> 1024.65 | D8: ='Monthly cash runway'!D7*SUM('Plan mix'!E5,'Plan mix'!E6,'Plan mix'!E7,'Plan mix'!E8) -> 1592.8605 | E8: ='Monthly cash runway'!E7*SUM('Plan mix'!E5,'Plan mix'!E6,'Plan mix'!E7,'Plan mix'!E8) -> 2203.9197 | F8: ='Monthly cash runway'!F7*SUM('Plan mix'!E5,'Plan mix'!E6,'Plan mix'!E7,'Plan mix'!E8) -> 2862.5316 | G8: ='Monthly cash runway'!G7*SUM('Plan mix'!E5,'Plan mix'!E6,'Plan mix'!E7,'Plan mix'!E8) -> 3573.8581 | H8: ='Monthly cash runway'!H7*SUM('Plan mix'!E5,'Plan mix'!E6,'Plan mix'!E7,'Plan mix'!E8) -> 4343.565 | I8: ='Monthly cash runway'!I7*SUM('Plan mix'!E5,'Plan mix'!E6,'Plan mix'!E7,'Plan mix'!E8) -> 5177.8731 | J8: ='Monthly cash runway'!J7*SUM('Plan mix'!E5,'Plan mix'!E6,'Plan mix'!E7,'Plan mix'!E8) -> 6083.6133 | K8: ='Monthly cash runway'!K7*SUM('Plan mix'!E5,'Plan mix'!E6,'Plan mix'!E7,'Plan mix'!E8) -> 7068.289 | L8: ='Monthly cash runway'!L7*SUM('Plan mix'!E5,'Plan mix'!E6,'Plan mix'!E7,'Plan mix'!E8) -> 8140.1429 | M8: ='Monthly cash runway'!M7*SUM('Plan mix'!E5,'Plan mix'!E6,'Plan mix'!E7,'Plan mix'!E8) -> 9308.2314 | N8: ='Monthly cash runway'!N7*SUM('Plan mix'!E5,'Plan mix'!E6,'Plan mix'!E7,'Plan mix'!E8) -> 10582.506 | O8: ='Monthly cash runway'!O7*SUM('Plan mix'!E5,'Plan mix'!E6,'Plan mix'!E7,'Plan mix'!E8) -> 11973.906 | P8: ='Monthly cash runway'!P7*SUM('Plan mix'!E5,'Plan mix'!E6,'Plan mix'!E7,'Plan mix'!E8) -> 13494.45 | Q8: ='Monthly cash runway'!Q7*SUM('Plan mix'!E5,'Plan mix'!E6,'Plan mix'!E7,'Plan mix'!E8) -> 15157.354 | R8: ='Monthly cash runway'!R7*SUM('Plan mix'!E5,'Plan mix'!E6,'Plan mix'!E7,'Plan mix'!E8) -> 16977.145 | S8: ='Monthly cash runway'!S7*SUM('Plan mix'!E5,'Plan mix'!E6,'Plan mix'!E7,'Plan mix'!E8) -> 18969.794 | T8: ='Monthly cash runway'!T7*SUM('Plan mix'!E5,'Plan mix'!E6,'Plan mix'!E7,'Plan mix'!E8) -> 21152.859 | U8: ='Monthly cash runway'!U7*SUM('Plan mix'!E5,'Plan mix'!E6,'Plan mix'!E7,'Plan mix'!E8) -> 23545.648 | V8: ='Monthly cash runway'!V7*SUM('Plan mix'!E5,'Plan mix'!E6,'Plan mix'!E7,'Plan mix'!E8) -> 26169.391 | W8: ='Monthly cash runway'!W7*SUM('Plan mix'!E5,'Plan mix'!E6,'Plan mix'!E7,'Plan mix'!E8) -> 29047.433 | X8: ='Monthly cash runway'!X7*SUM('Plan mix'!E5,'Plan mix'!E6,'Plan mix'!E7,'Plan mix'!E8) -> 32205.446 | Y8: ='Monthly cash runway'!Y7*SUM('Plan mix'!E5,'Plan mix'!E6,'Plan mix'!E7,'Plan mix'!E8) -> 35671.663 | Z8: ='Monthly cash runway'!Z7*SUM('Plan mix'!E5,'Plan mix'!E6,'Plan mix'!E7,'Plan mix'!E8) -> 39477.13
A9: Monthly gross profit | B9: 0 | C9: ='Monthly cash runway'!C7*SUM('Plan mix'!F5,'Plan mix'!F6,'Plan mix'!F7,'Plan mix'!F8) -> 991.83015 | D9: ='Monthly cash runway'!D7*SUM('Plan mix'!F5,'Plan mix'!F6,'Plan mix'!F7,'Plan mix'!F8) -> 1541.8407 | E9: ='Monthly cash runway'!E7*SUM('Plan mix'!F5,'Plan mix'!F6,'Plan mix'!F7,'Plan mix'!F8) -> 2133.3275 | F9: ='Monthly cash runway'!F7*SUM('Plan mix'!F5,'Plan mix'!F6,'Plan mix'!F7,'Plan mix'!F8) -> 2770.8438 | G9: ='Monthly cash runway'!G7*SUM('Plan mix'!F5,'Plan mix'!F6,'Plan mix'!F7,'Plan mix'!F8) -> 3459.3863 | H9: ='Monthly cash runway'!H7*SUM('Plan mix'!F5,'Plan mix'!F6,'Plan mix'!F7,'Plan mix'!F8) -> 4204.4393 | I9: ='Monthly cash runway'!I7*SUM('Plan mix'!F5,'Plan mix'!F6,'Plan mix'!F7,'Plan mix'!F8) -> 5012.0242 | J9: ='Monthly cash runway'!J7*SUM('Plan mix'!F5,'Plan mix'!F6,'Plan mix'!F7,'Plan mix'!F8) -> 5888.7534 | K9: ='Monthly cash runway'!K7*SUM('Plan mix'!F5,'Plan mix'!F6,'Plan mix'!F7,'Plan mix'!F8) -> 6841.8896 | L9: ='Monthly cash runway'!L7*SUM('Plan mix'!F5,'Plan mix'!F6,'Plan mix'!F7,'Plan mix'!F8) -> 7879.4116 | M9: ='Monthly cash runway'!M7*SUM('Plan mix'!F5,'Plan mix'!F6,'Plan mix'!F7,'Plan mix'!F8) -> 9010.0859 | N9: ='Monthly cash runway'!N7*SUM('Plan mix'!F5,'Plan mix'!F6,'Plan mix'!F7,'Plan mix'!F8) -> 10243.546 | O9: ='Monthly cash runway'!O7*SUM('Plan mix'!F5,'Plan mix'!F6,'Plan mix'!F7,'Plan mix'!F8) -> 11590.378 | P9: ='Monthly cash runway'!P7*SUM('Plan mix'!F5,'Plan mix'!F6,'Plan mix'!F7,'Plan mix'!F8) -> 13062.219 | Q9: ='Monthly cash runway'!Q7*SUM('Plan mix'!F5,'Plan mix'!F6,'Plan mix'!F7,'Plan mix'!F8) -> 14671.86 | R9: ='Monthly cash runway'!R7*SUM('Plan mix'!F5,'Plan mix'!F6,'Plan mix'!F7,'Plan mix'!F8) -> 16433.362 | S9: ='Monthly cash runway'!S7*SUM('Plan mix'!F5,'Plan mix'!F6,'Plan mix'!F7,'Plan mix'!F8) -> 18362.186 | T9: ='Monthly cash runway'!T7*SUM('Plan mix'!F5,'Plan mix'!F6,'Plan mix'!F7,'Plan mix'!F8) -> 20475.327 | U9: ='Monthly cash runway'!U7*SUM('Plan mix'!F5,'Plan mix'!F6,'Plan mix'!F7,'Plan mix'!F8) -> 22791.474 | V9: ='Monthly cash runway'!V7*SUM('Plan mix'!F5,'Plan mix'!F6,'Plan mix'!F7,'Plan mix'!F8) -> 25331.178 | W9: ='Monthly cash runway'!W7*SUM('Plan mix'!F5,'Plan mix'!F6,'Plan mix'!F7,'Plan mix'!F8) -> 28117.035 | X9: ='Monthly cash runway'!X7*SUM('Plan mix'!F5,'Plan mix'!F6,'Plan mix'!F7,'Plan mix'!F8) -> 31173.896 | Y9: ='Monthly cash runway'!Y7*SUM('Plan mix'!F5,'Plan mix'!F6,'Plan mix'!F7,'Plan mix'!F8) -> 34529.089 | Z9: ='Monthly cash runway'!Z7*SUM('Plan mix'!F5,'Plan mix'!F6,'Plan mix'!F7,'Plan mix'!F8) -> 38212.666
A10: Fixed costs | B10: 0 | C10: =IF('Model inputs'!B19="","",'Model inputs'!B19) -> 10500 | D10: =IF('Model inputs'!B19="","",'Model inputs'!B19) -> 10500 | E10: =IF('Model inputs'!B19="","",'Model inputs'!B19) -> 10500 | F10: =IF('Model inputs'!B19="","",'Model inputs'!B19) -> 10500 | G10: =IF('Model inputs'!B19="","",'Model inputs'!B19) -> 10500 | H10: =IF('Model inputs'!B19="","",'Model inputs'!B19) -> 10500 | I10: =IF('Model inputs'!B19="","",'Model inputs'!B19) -> 10500 | J10: =IF('Model inputs'!B19="","",'Model inputs'!B19) -> 10500 | K10: =IF('Model inputs'!B19="","",'Model inputs'!B19) -> 10500 | L10: =IF('Model inputs'!B19="","",'Model inputs'!B19) -> 10500 | M10: =IF('Model inputs'!B19="","",'Model inputs'!B19) -> 10500 | N10: =IF('Model inputs'!B19="","",'Model inputs'!B19) -> 10500 | O10: =IF('Model inputs'!B19="","",'Model inputs'!B19) -> 10500 | P10: =IF('Model inputs'!B19="","",'Model inputs'!B19) -> 10500 | Q10: =IF('Model inputs'!B19="","",'Model inputs'!B19) -> 10500 | R10: =IF('Model inputs'!B19="","",'Model inputs'!B19) -> 10500 | S10: =IF('Model inputs'!B19="","",'Model inputs'!B19) -> 10500 | T10: =IF('Model inputs'!B19="","",'Model inputs'!B19) -> 10500 | U10: =IF('Model inputs'!B19="","",'Model inputs'!B19) -> 10500 | V10: =IF('Model inputs'!B19="","",'Model inputs'!B19) -> 10500 | W10: =IF('Model inputs'!B19="","",'Model inputs'!B19) -> 10500 | X10: =IF('Model inputs'!B19="","",'Model inputs'!B19) -> 10500 | Y10: =IF('Model inputs'!B19="","",'Model inputs'!B19) -> 10500 | Z10: =IF('Model inputs'!B19="","",'Model inputs'!B19) -> 10500
A11: Net cash flow | B11: 0 | C11: ='Monthly cash runway'!C9-'Monthly cash runway'!C10 -> -9508.1699 | D11: ='Monthly cash runway'!D9-'Monthly cash runway'!D10 -> -8958.1593 | E11: ='Monthly cash runway'!E9-'Monthly cash runway'!E10 -> -8366.6725 | F11: ='Monthly cash runway'!F9-'Monthly cash runway'!F10 -> -7729.1562 | G11: ='Monthly cash runway'!G9-'Monthly cash runway'!G10 -> -7040.6137 | H11: ='Monthly cash runway'!H9-'Monthly cash runway'!H10 -> -6295.5607 | I11: ='Monthly cash runway'!I9-'Monthly cash runway'!I10 -> -5487.9758 | J11: ='Monthly cash runway'!J9-'Monthly cash runway'!J10 -> -4611.2466 | ... Z11: ='Monthly cash runway'!Z9-'Monthly cash runway'!Z10 -> 27712.666
A12: Cash balance | B12: =100000 -> 100000 | C12: ='Monthly cash runway'!B12+'Monthly cash runway'!C11 -> 90491.83 | D12: ='Monthly cash runway'!C12+'Monthly cash runway'!D11 -> 81533.671 | E12: ='Monthly cash runway'!D12+'Monthly cash runway'!E11 -> 73166.998 | F12: ='Monthly cash runway'!E12+'Monthly cash runway'!F11 -> 65437.842 | G12: ='Monthly cash runway'!F12+'Monthly cash runway'!G11 -> 58397.228 | H12: ='Monthly cash runway'!G12+'Monthly cash runway'!H11 -> 52101.668 | I12: ='Monthly cash runway'!H12+'Monthly cash runway'!I11 -> 46613.692 | J12: ='Monthly cash runway'!I12+'Monthly cash runway'!J11 -> 42002.445 | ... Z12: ='Monthly cash runway'!Y12+'Monthly cash runway'!Z11 -> 182728.05
A13: Months of runway left | B13: 0 | C13: =IF(IF(IF(ISERROR('Monthly cash runway'!C11<0),'Monthly cash runway'!C11<0,IF('Monthly cash runway'!C11="","",'Monthly cash runway'!C11<0))="",FALSE,IF(ISERROR('Monthly cash runway'!C11<0),'Monthly cash runway'!C11<0,IF('Monthly cash runway'!C11="","",'Monthly cash runway'!C11<0))),'Monthly cash runway'!C12/(0-'Monthly cash runway'!C11),"") -> 9.5172711 | D13: =IF(IF(IF(ISERROR('Monthly cash runway'!D11<0),'Monthly cash runway'!D11<0,IF('Monthly cash runway'!D11="","",'Monthly cash runway'!D11<0))="",FALSE,IF(ISERROR('Monthly cash runway'!D11<0),'Monthly cash runway'!D11<0,IF('Monthly cash runway'!D11="","",'Monthly cash runway'!D11<0))),'Monthly cash runway'!D12/(0-'Monthly cash runway'!D11),"") -> 9.1016098 | E13: =IF(IF(IF(ISERROR('Monthly cash runway'!E11<0),'Monthly cash runway'!E11<0,IF('Monthly cash runway'!E11="","",'Monthly cash runway'!E11<0))="",FALSE,IF(ISERROR('Monthly cash runway'!E11<0),'Monthly cash runway'!E11<0,IF('Monthly cash runway'!E11="","",'Monthly cash runway'!E11<0))),'Monthly cash runway'!E12/(0-'Monthly cash runway'!E11),"") -> 8.7450534 | F13: =IF(IF(IF(ISERROR('Monthly cash runway'!F11<0),'Monthly cash runway'!F11<0,IF('Monthly cash runway'!F11="","",'Monthly cash runway'!F11<0))="",FALSE,IF(ISERROR('Monthly cash runway'!F11<0),'Monthly cash runway'!F11<0,IF('Monthly cash runway'!F11="","",'Monthly cash runway'!F11<0))),'Monthly cash runway'!F12/(0-'Monthly cash runway'!F11),"") -> 8.4663631 | G13: =IF(IF(IF(ISERROR('Monthly cash runway'!G11<0),'Monthly cash runway'!G11<0,IF('Monthly cash runway'!G11="","",'Monthly cash runway'!G11<0))="",FALSE,IF(ISERROR('Monthly cash runway'!G11<0),'Monthly cash runway'!G11<0,IF('Monthly cash runway'!G11="","",'Monthly cash runway'!G11<0))),'Monthly cash runway'!G12/(0-'Monthly cash runway'!G11),"") -> 8.2943379 | H13: =IF(IF(IF(ISERROR('Monthly cash runway'!H11<0),'Monthly cash runway'!H11<0,IF('Monthly cash runway'!H11="","",'Monthly cash runway'!H11<0))="",FALSE,IF(ISERROR('Monthly cash runway'!H11<0),'Monthly cash runway'!H11<0,IF('Monthly cash runway'!H11="","",'Monthly cash runway'!H11<0))),'Monthly cash runway'!H12/(0-'Monthly cash runway'!H11),"") -> 8.2759377 | I13: =IF(IF(IF(ISERROR('Monthly cash runway'!I11<0),'Monthly cash runway'!I11<0,IF('Monthly cash runway'!I11="","",'Monthly cash runway'!I11<0))="",FALSE,IF(ISERROR('Monthly cash runway'!I11<0),'Monthly cash runway'!I11<0,IF('Monthly cash runway'!I11="","",'Monthly cash runway'!I11<0))),'Monthly cash runway'!I12/(0-'Monthly cash runway'!I11),"") -> 8.493786 | J13: =IF(IF(IF(ISERROR('Monthly cash runway'!J11<0),'Monthly cash runway'!J11<0,IF('Monthly cash runway'!J11="","",'Monthly cash runway'!J11<0))="",FALSE,IF(ISERROR('Monthly cash runway'!J11<0),'Monthly cash runway'!J11<0,IF('Monthly cash runway'!J11="","",'Monthly cash runway'!J11<0))),'Monthly cash runway'!J12/(0-'Monthly cash runway'!J11),"") -> 9.1086963 | ... Z13: =IF(IF(IF(ISERROR('Monthly cash runway'!Z11<0),'Monthly cash runway'!Z11<0,IF('Monthly cash runway'!Z11="","",'Monthly cash runway'!Z11<0))="",FALSE,IF(ISERROR('Monthly cash runway'!Z11<0),'Monthly cash runway'!Z11<0,IF('Monthly cash runway'!Z11="","",'Monthly cash runway'!Z11<0))),'Monthly cash runway'!Z12/(0-'Monthly cash runway'!Z11),"")

Sheet Model inputs
A1: Model inputs
A2: Integration values are aggregated snapshots; raw source records are not included.
A4: Variables
A5: Variable / segment | B5: Value
A6: Avg bisects per customer · Plan mix | B6: ='Runway assumptions'!B5 -> 50
A7: Card fee per invoice · Plan mix | B7: =0.3 -> 0.3
A8: Card fee rate · Plan mix | B8: =0.029 -> 0.029
A9: Customer pays LLM | B9: 0
A10: Customer pays LLM > A · Flat $199/repo | B10: =0 -> 0
A11: Customer pays LLM > A · Flat $49/repo | B11: =0 -> 0
A12: Customer pays LLM > B · BYOK + $99/repo | B12: =1 -> 1
A13: Customer pays LLM > C · $5 per bisect | B13: =0 -> 0
A14: LLM cost per bisect | B14: ='Model inputs'!B59*'Model inputs'!B64 -> 0
A15: LLM cost per bisect > Bisect (v2) | B15: ='Model inputs'!B60*'Model inputs'!B65 -> 0.252
A16: LLM cost per bisect > Fix & verify | B16: ='Model inputs'!B61*'Model inputs'!B66 -> 0
A17: LLM cost per bisect > Localise | B17: ='Model inputs'!B62*'Model inputs'!B67 -> 0
A18: Monthly churn | B18: ='Runway assumptions'!B7 -> 0.03
A19: Monthly fixed costs | B19: ='Model inputs'!B58*'Model inputs'!B57+'Model inputs'!B63 -> 10500
A20: New customer growth | B20: ='Runway assumptions'!B6 -> 0.1
A21: Price per bisect | B21: 0
A22: Price per bisect > A · Flat $199/repo | B22: =0 -> 0
A23: Price per bisect > A · Flat $49/repo | B23: =0 -> 0
A24: Price per bisect > B · BYOK + $99/repo | B24: =0 -> 0
A25: Price per bisect > C · $5 per bisect | B25: =5 -> 5
A26: Price per repo | B26: 0
A27: Price per repo > A · Flat $199/repo | B27: =199 -> 199
A28: Price per repo > A · Flat $49/repo | B28: =49 -> 49
A29: Price per repo > B · BYOK + $99/repo | B29: =99 -> 99
A30: Price per repo > C · $5 per bisect | B30: =0 -> 0
A31: Repos per customer · Plan mix | B31: =1 -> 1
A32: Weighted gross profit per customer | B32: ='Model inputs'!B47*'Model inputs'!B42 -> 0
A33: Weighted gross profit per customer > A · Flat $199/repo | B33: ='Model inputs'!B48*'Model inputs'!B43 -> 0
A34: Weighted gross profit per customer > A · Flat $49/repo | B34: ='Model inputs'!B49*'Model inputs'!B44 -> 0
A35: Weighted gross profit per customer > B · BYOK + $99/repo | B35: ='Model inputs'!B50*'Model inputs'!B45 -> 95.829
A36: Weighted gross profit per customer > C · $5 per bisect | B36: ='Model inputs'!B51*'Model inputs'!B46 -> 0
A37: Weighted revenue per customer | B37: ='Model inputs'!B47*'Model inputs'!B52 -> 0
A38: Weighted revenue per customer > A · Flat $199/repo | B38: ='Model inputs'!B48*'Model inputs'!B53 -> 0
A39: Weighted revenue per customer > A · Flat $49/repo | B39: ='Model inputs'!B49*'Model inputs'!B54 -> 0
A40: Weighted revenue per customer > B · BYOK + $99/repo | B40: ='Model inputs'!B50*'Model inputs'!B55 -> 99
A41: Weighted revenue per customer > C · $5 per bisect | B41: ='Model inputs'!B51*'Model inputs'!B56 -> 0
...
